```
TaskFailedException
```

Diese Ausnahme wird von einem [`wait(t)`](@ref) Aufruf ausgelöst, wenn die Aufgabe `t` fehlschlägt. `TaskFailedException` umschließt die fehlgeschlagene Aufgabe `t`.
