```
TaskFailedException
```

Cette exception est lancée par un appel à [`wait(t)`](@ref) lorsque la tâche `t` échoue. `TaskFailedException` enveloppe la tâche échouée `t`.
