```
TaskFailedException
```

此异常由 [`wait(t)`](@ref) 调用抛出，当任务 `t` 失败时。`TaskFailedException` 包装了失败的任务 `t`。
